Workbook

Sheet Read me
A2: Worksheets Guide
A4: Search Strings | B4: Search strings used in the systematic review
A5: Relevance Ratings | B5: Relevance ratings definitions
A6: References | B6: The list of source documents
A7: Inflation | B7: Inflation indices used to convert to 2017 values
A8: Currency | B8: Exchange rates used to convert to €
A9: Res, Cap, Agg, Pro Costs | B9: The normalised data used in Figures 2-5
A10: Capacity Credit | B10: The data used in Figure 6
A11: Curtailment | B11: The data used in Supplementary Figures 1 and 2 (in Supplementary Information)

Sheet Search Strings
A1: Wind AND (intermittent OR intermittency OR variable generation)
A2: Solar AND (intermittent OR intermittency OR variable generation)
A3: Storage AND (intermittent OR intermittency OR variable generation)
A4: Renewable AND (intermittent OR intermittency OR variable generation)
A5: Network AND (wind OR solar OR storage)
A6: Grid AND (wind OR solar OR storage)
A7: Transmission AND (wind OR solar OR storage)
A8: Capacity credit AND (wind OR solar OR storage)
A9: Capacity margin AND (wind OR solar OR storage)
A10: System reserve AND (wind OR solar OR storage)
A11: System balancing AND (wind OR solar OR storage)
A12: Load factor AND (wind OR solar OR storage)
... A19: Profile cost AND variable renewables

Sheet Relevance Ratings
A1: Relevance rating | B1: Definition
A2: 1 | B2: Article shows clear data on at least one of the terms above
A3: 2 | B3: Article shows clear data on at least one of the terms above, however, misses some data or uses an uncommon metric
A4: 3 | B4: Article mentions at least one of the terms above, however, does not include relevant data
A5: 4 | B5: Irrelevant article or duplicate

Sheet References
A1: Reference ID | B1: Search term | C1: Source | D1: Searched by | E1: Total number of returned documents | F1: Relevant literature | G1: Year | H1: Title | I1: Journal | J1: Leading author | K1: Link | L1: Ann.:
A3: 1 | B3: wind intermittency OR intermittent OR "variable generation" | C3: google scholar | D3: FS | E3: 91700 | F3: 2 | G3: 2007 | H3: The costs of wind’s intermittency in Germany: application of a stochastic electricity market model | I3: Euro. Trans. Electr. Power | J3: DJ Swider | K3: http://onlinelibrary.wiley.com/doi/10.1002/etep.125/pdf
A4: 2 | B4: wind intermittency OR intermittent OR "variable generation" | C4: google scholar | D4: FS | E4: 91700 | F4: 3 | G4: 2009 | H4: Intermittent wind generation in optimal power flow dispatching | I4: Generation, Transmission & Distribution | J4: RA Jabr | K4: http://ieeexplore.ieee.org/xpls/abs_all.jsp?arnumber=4721662&tag=1
A5: 3 | B5: wind intermittency OR intermittent OR "variable generation" | C5: google scholar | D5: FS | E5: 91700 | F5: 3 | G5: 2007 | H5: Controllable and affordable utility-scale electricity from intermittent wind resources and compressed air energy storage (CAES) | I5: Energy | J5: A Cavallo | K5: http://www.sciencedirect.com/science/article/pii/S0360544206000776
A6: 4 | B6: wind intermittency OR intermittent OR "variable generation" | C6: google scholar | D6: FS | E6: 91700 | F6: 2 | G6: 2006 | H6: A Stochastic Unit-commitment Model for the Evaluation of the Impacts of Integration of Large Amounts of Intermittent Wind Power | I6: Probabilistic Methods Applied to Power Systems | J6: R Barth | K6: http://ieeexplore.ieee.org/xpls/abs_all.jsp?arnumber=4202207&tag=1
A7: 5 | B7: wind intermittency OR intermittent OR "variable generation" | C7: google scholar | D7: FS | E7: 91700 | F7: 1 | G7: 2010 | H7: Overview of wind power intermittency impacts on power systems | I7: Electronic Power Systems Research | J7: MH Albadi | K7: http://www.sciencedirect.com/science/article/pii/S0378779609002764
A8: 6 | B8: wind intermittency OR intermittent OR "variable generation" | C8: google scholar | D8: FS | E8: 91700 | F8: 1 | G8: 2006 | H8: The economics of large-scale wind power in a carbon constrained world | I8: Energy Policy | J8: JF DeCarolis | K8: http://www.sciencedirect.com/science/article/pii/S0301421504001740
A9: 7 | B9: wind intermittency OR intermittent OR "variable generation" | C9: google scholar | D9: FS | E9: 91700 | F9: 3 | G9: 2009 | H9: The intermittency of wind, solar, and renewable electricity generators: Technical barrier or rhetorical excuse? | I9: Utilities Policy | J9: BK Sovacool | K9: http://www.sciencedirect.com/science/article/pii/S0957178708000611
A10: 8 | B10: wind intermittency OR intermittent OR "variable generation" | C10: google scholar | D10: FS | E10: 91700 | F10: 3 | G10: 2010 | H10: A review of wind power and wind speed forecasting methods with different time horizons | I10: North American Power Symposium | J10: SS Soman | K10: http://ieeexplore.ieee.org/xpls/abs_all.jsp?arnumber=5619586
A11: 9 | B11: wind intermittency OR intermittent OR "variable generation" | C11: google scholar | D11: FS | E11: 91700 | F11: 2 | G11: 2007 | H11: Supplying Baseload Power and Reducing Transmission Requirements by Interconnecting Wind Farms | I11: J. Appl. Meteor. Climatol. | J11: CL Archer | K11: http://journals.ametsoc.org/doi/abs/10.1175/2007JAMC1538.1
A12: 10 | B12: wind intermittency OR intermittent OR "variable generation" | C12: google scholar | D12: FS | E12: 91700 | F12: 3 | G12: 2010 | H12: Wind Power | I12: Cambridge University Press (Book) | J12: P Musgrove | K12: http://www.langtoninfo.com/web_content/9780521762380_frontmatter.pdf
A13: 11 | B13: wind intermittency OR intermittent OR "variable generation" | C13: google scholar | D13: FS | E13: 91700 | F13: 2 | G13: 2007 | H13: Exploring the impact on cost and electricity production of high penetration levels of intermittent electricity in OECD Europe and the USA, results for wind energy | I13: Energy | J13: M Hoogwijk | K13: http://www.sciencedirect.com/science/article/pii/S0360544206002544
A14: 12 | B14: wind intermittency OR intermittent OR "variable generation" | C14: google scholar | D14: FS | E14: 91700 | F14: 3 | G14: 2008 | H14: Security-Constrained Unit Commitment With Volatile Wind Power Generation | I14: Power Systems | J14: J Wang | K14: http://ieeexplore.ieee.org/xpls/abs_all.jsp?arnumber=4556639
... A192: 190 | B192: Network wind OR solar OR storage | C192: google scholar | D192: FS | E192: 1430000 | F192: 4 | G192: 2012 | H192: A Novel Distributed Direct-Voltage Control Strategy for Grid Integration of Offshore Wind Energy Systems Through MTDC Network | I192: Industrial Electronics | J192: RT Pinto | K192: http://ieeexplore.ieee.org/xpls/abs_all.jsp?arnumber=6290374
A193: 191 | B193: Network wind OR solar OR storage | C193: google scholar | D193: FS | E193: 1430000 | F193: 3 | G193: 2011 | H193: Modal Analysis of a DFIG-Based Wind Farm Interfaced With a Series Compensated Network | I193: Energy Conversion | J193: L Fan | K193: http://ieeexplore.ieee.org/stamp/stamp.jsp?tp=&arnumber=5982088 | L193: intertia - tech
A194: 192 | B194: Network wind OR solar OR storage | C194: google scholar | D194: FS | E194: 1430000 | F194: 4 | G194: 2009 | H194: A review on the forecasting of wind speed and generated power | I194: Renewable and Sustainable Energy Reviews | J194: M Lei | K194: http://www.sciencedirect.com/science/article/pii/S1364032108000282
A195: 193 | B195: Network wind OR solar OR storage | C195: google scholar | D195: FS | E195: 1430000 | F195: 4 | G195: 2011 | H195: Short-term wind power forecasting using ridgelet neural network | I195: Electric Power Systems Research | J195: N Amjady | K195: http://www.sciencedirect.com/science/article/pii/S0378779611001945
A196: 194 | B196: Network wind OR solar OR storage | C196: google scholar | D196: FS | E196: 1430000 | F196: 4 | G196: 2007 | H196: Real-Time and Off-Line Simulation of a Detailed Wind Farm Model Connected to a Multi-Bus Network | I196: Electrical Power Conference | J196: JN Paquin | K196: http://ieeexplore.ieee.org/xpls/abs_all.jsp?arnumber=4520321
A197: 195 | B197: Network wind OR solar OR storage | C197: google scholar | D197: FS | E197: 1430000 | F197: 4 | G197: 2006 | H197: Output power leveling of wind farm using pitch angle control with fuzzy neural network | I197: Power Engineering Society General Meeting | J197: T Senjyu | K197: http://ieeexplore.ieee.org/xpls/abs_all.jsp?arnumber=1709377
A198: 196 | B198: Grid wind OR solar OR storage | C198: google scholar | D198: FS | E198: 1170000 | F198: 3 | G198: 2010 | H198: The economics of using plug-in hybrid electric vehicle battery packs for grid storage | I198: Journal of Power Sources | J198: SB Peterson | K198: http://www.sciencedirect.com/science/article/pii/S0378775309017303
A199: 197 | B199: Grid wind OR solar OR storage | C199: google scholar | D199: FS | E199: 1170000 | F199: 3 | G199: 2011 | H199: Electrical Energy Storage for the Grid: A Battery of Choices | I199: Science | J199: B Dunn | K199: http://www.sciencemag.org/content/334/6058/928.short
A200: 198 | B200: Grid wind OR solar OR storage | C200: google scholar | D200: FS | E200: 1170000 | F200: 4 | G200: 2012 | H200: Battery energy storage and wind energy integrated into the Smart Grid | I200: Innovative Smart Grid Technologies | J200: MC Such | K200: http://ieeexplore.ieee.org/xpl/articleDetails.jsp?arnumber=6175772&tag=1
A201: 199 | B201: Grid wind OR solar OR storage | C201: google scholar | D201: FS | E201: 1170000 | F201: 4 | G201: 2007 | H201: Kriegers flak 640 MW off-shore wind power grid connection—A real project case study | I201: Energy Conversion | J201: D Andersson | K201: http://ieeexplore.ieee.org/xpls/abs_all.jsp?arnumber=4105992
A202: 200 | B202: Grid wind OR solar OR storage | C202: google scholar | D202: FS | E202: 1170000 | F202: 4 | G202: 2010 | H202: A new conversion and control system for a small off-grid wind turbine | I202: Optimization of Electrical and Electronic Equipment (OPTIM) | J202: N Muntean | K202: http://ieeexplore.ieee.org/xpls/abs_all.jsp?arnumber=5510367
A203: 201 | B203: Grid wind OR solar OR storage | C203: google scholar | D203: FS | E203: 1170000 | F203: 4 | G203: 2006 | H203: Control of permanent-magnet generators applied to variable-speed wind-energy systems connected to the grid | I203: Energy Conversion | J203: M Chinchilla | K203: http://ieeexplore.ieee.org/xpls/abs_all.jsp?arnumber=1597329
A204: 202 | B204: Grid wind OR solar OR storage | C204: google scholar | D204: FS | E204: 1170000 | F204: 4 | G204: 2011 | H204: Grid Converters for Photovoltaic and Wind Power Systems | I204: Book | J204: R Teodorescu | K204: https://books.google.co.uk/books?hl=en&lr=&id=5k4tmcVIaM0C&oi=fnd&pg=PP10&dq=Grid++wind+OR+solar+OR+storage&ots=vbPYeH9jws&sig=J0KunCLPuEEUoCzCdfhf8Hj9BAY#v=onepage&q=Grid%20%20wind%20OR%20solar%20OR%20storage&f=false
A205: 203 | B205: Grid wind OR solar OR storage | C205: google scholar | D205: FS | E205: 1170000 | F205: 4 | G205: 2011 | H205: Electrochemical Energy Storage for Green Grid | I205: Chemical Reviews | J205: Z Yang | K205: http://pubs.acs.org/doi/full/10.1021/cr100290v | L205: data from different source but relevant
A206: 204 | B206: Grid wind OR solar OR storage | C206: google scholar | D206: FS | E206: 1170000 | F206: 3 | G206: 2006 | H206: Advanced grid requirements for the integration of wind turbines into the German transmission system | I206: Power Engineering Society General Meeting | J206: I Erlich | K206: http://ieeexplore.ieee.org/xpls/abs_all.jsp?arnumber=1709340
A207: 205 | B207: Grid wind OR solar OR storage | C207: google scholar | D207: FS | E207: 1170000 | F207: 4 | G207: 2010 | H207: Energy Storage Systems for Transport and Grid Applications | I207: Industrial Electronics | J207: S Vazquez | K207: http://ieeexplore.ieee.org/xpls/abs_all.jsp?arnumber=5582228
A208: 206 | B208: Grid wind OR solar OR storage | C208: google scholar | D208: FS | E208: 1170000 | F208: 4 | G208: 2010 | H208: Grid stability battery systems for renewable energy success | I208: Energy Conversion Congress and Exposition | J208: C Vartanian | K208: http://ieeexplore.ieee.org/xpls/abs_all.jsp?arnumber=5618059
A209: 207 | B209: Grid wind OR solar OR storage | C209: google scholar | D209: FS | E209: 1170000 | F209: 3 | G209: 2010 | H209: A Reliability Perspective of the Smart Grid | I209: Smart Grid | J209: K Moslehi | K209: http://ieeexplore.ieee.org/xpls/abs_all.jsp?arnumber=5467283
A210: 208 | B210: Grid wind OR solar OR storage | C210: google scholar | D210: FS | E210: 1170000 | F210: 2 | G210: 2010 | H210: Agent-based micro-storage management for the Smart Grid | I210: AAMAS '10 | J210: P Vytelingum | K210: http://dl.acm.org/citation.cfm?id=1838212
A211: 209 | B211: Grid wind OR solar OR storage | C211: google scholar | D211: FS | E211: 1170000 | F211: 4 | G211: 2010 | H211: A 24-h forecast of solar irradiance using artificial neural network: Application for performance prediction of a grid-connected PV plant at Trieste, Italy | I211: Solar Energy | J211: A Mellit | K211: http://www.sciencedirect.com/science/article/pii/S0038092X10000782
A212: 210 | B212: Grid wind OR solar OR storage | C212: google scholar | D212: FS | E212: 1170000 | F212: 3 | G212: 2008 | H212: Intelligent Scheduling of Hybrid and Electric Vehicle Storage Capacity in a Parking Lot for Profit Maximization in Grid Power Transactions | I212: Energy 2030 Conference | J212: C Hutson | K212: http://ieeexplore.ieee.org/xpls/abs_all.jsp?arnumber=4781051&tag=1
A213: 211 | B213: Grid wind OR solar OR storage | C213: google scholar | D213: FS | E213: 1170000 | F213: 4 | G213: 2010 | H213: Overview of recent grid codes for wind power integration | I213: Optimization of Electrical and Electronic Equipment (OPTIM) | J213: M Altın | K213: http://ieeexplore.ieee.org/xpls/abs_all.jsp?arnumber=5510521&tag=1 | L213: intertia
A214: 212 | B214: Grid wind OR solar OR storage | C214: google scholar | D214: FS | E214: 1170000 | F214: 3 | G214: 2008 | H214: Challenges in integrating distributed Energy storage systems into future smart grid | I214: Industrial Electronics | J214: A Mohd | K214: http://ieeexplore.ieee.org/xpls/abs_all.jsp?arnumber=4676896
A215: 213 | B215: Grid wind OR solar OR storage | C215: google scholar | D215: FS | E215: 1170000 | F215: 4 | G215: 2008 | H215: Stability augmentation of a grid-connected wind farm | I215: Book | J215: SM Muyeen | K215: https://books.google.co.uk/books?hl=en&lr=&id=RYRfCJNm6LcC&oi=fnd&pg=PA1&dq=Grid++wind+OR+solar+OR+storage&ots=t2xJST6S9Q&sig=ZobJF56tPW4JAI-GvJnEreWvlOE#v=onepage&q=Grid%20%20wind%20OR%20solar%20OR%20storage&f=false
A216: 214 | B216: Grid wind OR solar OR storage | C216: google scholar | D216: FS | E216: 1170000 | F216: 3 | G216: 2006 | H216: Integrating Large Wind Farms into Weak Power Grids with Long Transmission Lines | I216: Power Electronics and Motion Control Conference | J216: R Piwko | K216: http://ieeexplore.ieee.org/xpls/abs_all.jsp?arnumber=4778165
A217: 215 | B217: Grid wind OR solar OR storage | C217: google scholar | D217: FS | E217: 1170000 | F217: 1 | G217: 2009 | H217: The economics of wind energy | I217: EWEA Report | J217: Sarah Clifford | K217: https://books.google.co.uk/books?hl=en&lr=&id=3Uv5PEJYwvMC&oi=fnd&pg=PA8&dq=Grid++wind+OR+solar+OR+storage&ots=kQktdkZeGd&sig=dqD-MFyhNK_L1CNlEXbyuvd3lQ0#v=onepage&q=Grid%20%20wind%20OR%20solar%20OR%20storage&f=false
A218: 216 | B218: Grid wind OR solar OR storage | C218: google scholar | D218: FS | E218: 1170000 | F218: 3 | G218: 2010 | H218: Optimal Charging Strategies for Unidirectional Vehicle-to-Grid | I218: Smart Grid | J218: E Sortomme | K218: http://ieeexplore.ieee.org/xpls/abs_all.jsp?arnumber=5661888&tag=1
...

Sheet Res, Cap, Agg, Pro Costs
A1: Operating reserve Costs | F1: Capacity Costs | K1: Aggregated Costs | T1: Profile Costs
A2: ID | B2: Penetration level | C2: 2017 €/MWh | D2: Region | F2: ID | G2: Penetration level | H2: 2017 €/MWh | I2: Region | K2: ID | L2: Year | M2: CCY | N2: Penetration level | O2: 2015 £/MWh | P2: 2017 €/MWh | Q2: Region | R2: Notes | T2: ID | U2: Year | V2: CCY | W2: Penetration level | X2: Reported value | Y2: 2017 €/MWh | Z2: Region | AA2: Notes
A3: 17 | B3: 0.4 | C3: 26.232572 | D3: n/a | F3: 50 | G3: 0.2 | H3: 0.92899907 | I3: UK | K3: 403/455 | L3: 2015 | M3: GBP | N3: 0.364 | O3: 6.4 | P3: =O3*(1/(INDEX(Currency!$A$1:$E$20,MATCH(L3,Currency!$A$1:$A$20,0),MATCH(M3,Currency!$A$1:$E$1,0))))*(Inflation!$B$23/(VLOOKUP(L3,Inflation!$A$1:$B$23,2,FALSE))) -> 8.9942435 | Q3: UK | R3: Offshore wind, CCC 2015 | T3: 347 | U3: 2001 | V3: EUR | W3: 0.02 | X3: -1 | Y3: =X3*(1/(INDEX(Currency!$A$1:$E$20,MATCH(U3,Currency!$A$1:$A$20,0),MATCH(V3,Currency!$A$1:$E$1,0))))*(Inflation!$B$23/(VLOOKUP(U3,Inflation!$A$1:$B$23,2,FALSE))) -> -1.3352102 | Z3: Germany | AA3: Wind, Table 3
A4: 17 | B4: 0.8 | C4: 17.657365 | D4: n/a | F4: 400 | G4: 0.02 | H4: 6.1507992 | I4: in Austria | K4: 403/455 | L4: 2015 | M4: GBP | N4: 0.363 | O4: 13.6 | P4: =O4*(1/(INDEX(Currency!$A$1:$E$20,MATCH(L4,Currency!$A$1:$A$20,0),MATCH(M4,Currency!$A$1:$E$1,0))))*(Inflation!$B$23/(VLOOKUP(L4,Inflation!$A$1:$B$23,2,FALSE))) -> 19.112767 | Q4: UK | R4: Offshore wind, CCC 2015 | T4: 347 | U4: 2004 | V4: EUR | W4: 0.03 | X4: 0 | Y4: =X4*(1/(INDEX(Currency!$A$1:$E$20,MATCH(U4,Currency!$A$1:$A$20,0),MATCH(V4,Currency!$A$1:$E$1,0))))*(Inflation!$B$23/(VLOOKUP(U4,Inflation!$A$1:$B$23,2,FALSE))) -> 0 | Z4: Germany | AA4: Wind, Table 3
A5: 50 | B5: 0.04 | C5: 0.034407373 | D5: UK | F5: 400 | G5: 0.04 | H5: 8.5086056 | I5: in Austria | K5: 403/455 | L5: 2015 | M5: GBP | N5: 0.361 | O5: 23 | P5: =O5*(1/(INDEX(Currency!$A$1:$E$20,MATCH(L5,Currency!$A$1:$A$20,0),MATCH(M5,Currency!$A$1:$E$1,0))))*(Inflation!$B$23/(VLOOKUP(L5,Inflation!$A$1:$B$23,2,FALSE))) -> 32.323062 | Q5: UK | R5: Offshore wind, CCC 2015 | T5: 347 | U5: 2005 | V5: EUR | W5: 0.035 | X5: 0 | Y5: =X5*(1/(INDEX(Currency!$A$1:$E$20,MATCH(U5,Currency!$A$1:$A$20,0),MATCH(V5,Currency!$A$1:$E$1,0))))*(Inflation!$B$23/(VLOOKUP(U5,Inflation!$A$1:$B$23,2,FALSE))) -> 0 | Z5: Germany | AA5: Wind, Table 3
A6: 50 | B6: 0.08 | C6: 0.13762949 | D6: UK | F6: 400 | G6: 0.06 | H6: 10.866412 | I6: in Austria | K6: 403/455 | L6: 2015 | M6: GBP | N6: 0.47 | O6: 36.9 | P6: =O6*(1/(INDEX(Currency!$A$1:$E$20,MATCH(L6,Currency!$A$1:$A$20,0),MATCH(M6,Currency!$A$1:$E$1,0))))*(Inflation!$B$23/(VLOOKUP(L6,Inflation!$A$1:$B$23,2,FALSE))) -> 51.857435 | Q6: UK | R6: Offshore wind, CCC 2015 | T6: 347 | U6: 2006 | V6: EUR | W6: 0.047 | X6: 2 | Y6: =X6*(1/(INDEX(Currency!$A$1:$E$20,MATCH(U6,Currency!$A$1:$A$20,0),MATCH(V6,Currency!$A$1:$E$1,0))))*(Inflation!$B$23/(VLOOKUP(U6,Inflation!$A$1:$B$23,2,FALSE))) -> 2.4086453 | Z6: Germany | AA6: Wind, Table 3
A7: 50 | B7: 0.12 | C7: 0.2580553 | D7: UK | F7: 400 | G7: 0.08 | H7: 11.994059 | I7: in Austria | K7: 403/455 | L7: 2015 | M7: GBP | N7: 0.48 | O7: 35.4 | P7: =O7*(1/(INDEX(Currency!$A$1:$E$20,MATCH(L7,Currency!$A$1:$A$20,0),MATCH(M7,Currency!$A$1:$E$1,0))))*(Inflation!$B$23/(VLOOKUP(L7,Inflation!$A$1:$B$23,2,FALSE))) -> 49.749409 | Q7: UK | R7: Offshore wind, CCC 2015 | T7: 347 | U7: 2007 | V7: EUR | W7: 0.049 | X7: 5 | Y7: =X7*(1/(INDEX(Currency!$A$1:$E$20,MATCH(U7,Currency!$A$1:$A$20,0),MATCH(V7,Currency!$A$1:$E$1,0))))*(Inflation!$B$23/(VLOOKUP(U7,Inflation!$A$1:$B$23,2,FALSE))) -> 5.8840162 | Z7: Germany | AA7: Wind, Table 3
A8: 50 | B8: 0.16 | C8: 0.3784811 | D8: UK | F8: 400 | G8: 0.1 | H8: 12.609138 | I8: in Austria | K8: 403/455 | L8: 2015 | M8: GBP | N8: 0.512 | O8: 13.9 | P8: =O8*(1/(INDEX(Currency!$A$1:$E$20,MATCH(L8,Currency!$A$1:$A$20,0),MATCH(M8,Currency!$A$1:$E$1,0))))*(Inflation!$B$23/(VLOOKUP(L8,Inflation!$A$1:$B$23,2,FALSE))) -> 19.534373 | Q8: UK | R8: Offshore wind, CCC 2015 | T8: 347 | U8: 2008 | V8: EUR | W8: 0.055 | X8: 6 | Y8: =X8*(1/(INDEX(Currency!$A$1:$E$20,MATCH(U8,Currency!$A$1:$A$20,0),MATCH(V8,Currency!$A$1:$E$1,0))))*(Inflation!$B$23/(VLOOKUP(U8,Inflation!$A$1:$B$23,2,FALSE))) -> 6.8116232 | Z8: Germany | AA8: Wind, Table 3
A9: 50 | B9: 0.2 | C9: 0.51611059 | D9: UK | F9: 400 | G9: 0.12 | H9: 13.121705 | I9: in Austria | K9: 403/455 | L9: 2015 | M9: GBP | N9: 0.518 | O9: 12.8 | P9: =O9*(1/(INDEX(Currency!$A$1:$E$20,MATCH(L9,Currency!$A$1:$A$20,0),MATCH(M9,Currency!$A$1:$E$1,0))))*(Inflation!$B$23/(VLOOKUP(L9,Inflation!$A$1:$B$23,2,FALSE))) -> 17.988487 | Q9: UK | R9: Offshore wind, CCC 2015 | T9: 347 | U9: 2009 | V9: EUR | W9: 0.071 | X9: 3 | Y9: =X9*(1/(INDEX(Currency!$A$1:$E$20,MATCH(U9,Currency!$A$1:$A$20,0),MATCH(V9,Currency!$A$1:$E$1,0))))*(Inflation!$B$23/(VLOOKUP(U9,Inflation!$A$1:$B$23,2,FALSE))) -> 3.3723955 | Z9: Germany | AA9: Wind, Table 3
A10: 50 | B10: 0.04 | C10: 0.086018432 | D10: UK | F10: 400 | G10: 0.14 | H10: 13.531758 | I10: in Austria | K10: 403/455 | L10: 2015 | M10: GBP | N10: 0.513 | O10: 7.1 | P10: =O10*(1/(INDEX(Currency!$A$1:$E$20,MATCH(L10,Currency!$A$1:$A$20,0),MATCH(M10,Currency!$A$1:$E$1,0))))*(Inflation!$B$23/(VLOOKUP(L10,Inflation!$A$1:$B$23,2,FALSE))) -> 9.9779888 | Q10: UK | R10: Offshore wind, CCC 2015 | T10: 347 | U10: 2010 | V10: EUR | W10: 0.073 | X10: 2 | Y10: =X10*(1/(INDEX(Currency!$A$1:$E$20,MATCH(U10,Currency!$A$1:$A$20,0),MATCH(V10,Currency!$A$1:$E$1,0))))*(Inflation!$B$23/(VLOOKUP(U10,Inflation!$A$1:$B$23,2,FALSE))) -> 2.2023758 | Z10: Germany | AA10: Wind, Table 3
A11: 50 | B11: 0.08 | C11: 0.2580553 | D11: UK | F11: 400 | G11: 0.16 | H11: 13.736785 | I11: in Austria | K11: 403/455 | L11: 2015 | M11: GBP | N11: 0.519 | O11: 8.2 | P11: =O11*(1/(INDEX(Currency!$A$1:$E$20,MATCH(L11,Currency!$A$1:$A$20,0),MATCH(M11,Currency!$A$1:$E$1,0))))*(Inflation!$B$23/(VLOOKUP(L11,Inflation!$A$1:$B$23,2,FALSE))) -> 11.523874 | Q11: UK | R11: Offshore wind, CCC 2015 | T11: 347 | U11: 2011 | V11: EUR | W11: 0.088 | X11: 3 | Y11: =X11*(1/(INDEX(Currency!$A$1:$E$20,MATCH(U11,Currency!$A$1:$A$20,0),MATCH(V11,Currency!$A$1:$E$1,0))))*(Inflation!$B$23/(VLOOKUP(U11,Inflation!$A$1:$B$23,2,FALSE))) -> 3.2042526 | Z11: Germany | AA11: Wind, Table 3
A12: 50 | B12: 0.12 | C12: 0.46449953 | D12: UK | F12: 400 | G12: 0.18 | H12: 13.941812 | I12: in Austria | K12: 456 | L12: 2015 | M12: GBP | N12: 0.266 | O12: 10.6 | P12: =O12*(1/(INDEX(Currency!$A$1:$E$20,MATCH(L12,Currency!$A$1:$A$20,0),MATCH(M12,Currency!$A$1:$E$1,0))))*(Inflation!$B$23/(VLOOKUP(L12,Inflation!$A$1:$B$23,2,FALSE))) -> 14.896716 | Q12: UK | R12: Offshore wind, No progress | T12: 347 | U12: 2012 | V12: EUR | W12: 0.08 | X12: 5 | Y12: =X12*(1/(INDEX(Currency!$A$1:$E$20,MATCH(U12,Currency!$A$1:$A$20,0),MATCH(V12,Currency!$A$1:$E$1,0))))*(Inflation!$B$23/(VLOOKUP(U12,Inflation!$A$1:$B$23,2,FALSE))) -> 5.2030819 | Z12: Germany | AA12: Wind, Table 3
A13: 50 | B13: 0.16 | C13: 0.70535114 | D13: UK | F13: 400 | G13: 0.02 | H13: 6.1507992 | I13: in Austria | K13: 456 | L13: 2015 | M13: GBP | N13: 0.37 | O13: 31.8 | P13: =O13*(1/(INDEX(Currency!$A$1:$E$20,MATCH(L13,Currency!$A$1:$A$20,0),MATCH(M13,Currency!$A$1:$E$1,0))))*(Inflation!$B$23/(VLOOKUP(L13,Inflation!$A$1:$B$23,2,FALSE))) -> 44.690147 | Q13: UK | R13: Offshore wind, No progress | T13: 347 | U13: 2006 | V13: EUR | W13: 0.004 | X13: -17 | Y13: =X13*(1/(INDEX(Currency!$A$1:$E$20,MATCH(U13,Currency!$A$1:$A$20,0),MATCH(V13,Currency!$A$1:$E$1,0))))*(Inflation!$B$23/(VLOOKUP(U13,Inflation!$A$1:$B$23,2,FALSE))) -> -20.473485 | Z13: Germany | AA13: Solar, Table 3
A14: 50 | B14: 0.2 | C14: 0.94620275 | D14: UK | F14: 400 | G14: 0.04 | H14: 8.5086056 | I14: in Austria | K14: 456 | L14: 2015 | M14: GBP | N14: 0.504 | O14: 48.4 | P14: =O14*(1/(INDEX(Currency!$A$1:$E$20,MATCH(L14,Currency!$A$1:$A$20,0),MATCH(M14,Currency!$A$1:$E$1,0))))*(Inflation!$B$23/(VLOOKUP(L14,Inflation!$A$1:$B$23,2,FALSE))) -> 68.018966 | Q14: UK | R14: Offshore wind, No progress | T14: 347 | U14: 2007 | V14: EUR | W14: 0.005 | X14: -6 | Y14: =X14*(1/(INDEX(Currency!$A$1:$E$20,MATCH(U14,Currency!$A$1:$A$20,0),MATCH(V14,Currency!$A$1:$E$1,0))))*(Inflation!$B$23/(VLOOKUP(U14,Inflation!$A$1:$B$23,2,FALSE))) -> -7.0608194 | Z14: Germany | AA14: Solar, Table 3
A15: 336 | B15: 0.33 | C15: 20.232619 | D15: California | F15: 400 | G15: 0.06 | H15: 10.558872 | I15: in Austria | K15: 456 | L15: 2015 | M15: GBP | N15: 0.266 | O15: 10.2 | P15: =O15*(1/(INDEX(Currency!$A$1:$E$20,MATCH(L15,Currency!$A$1:$A$20,0),MATCH(M15,Currency!$A$1:$E$1,0))))*(Inflation!$B$23/(VLOOKUP(L15,Inflation!$A$1:$B$23,2,FALSE))) -> 14.334576 | Q15: UK | R15: Offshore wind, Moderate progress | T15: 347 | U15: 2008 | V15: EUR | W15: 0.007 | X15: -16 | Y15: =X15*(1/(INDEX(Currency!$A$1:$E$20,MATCH(U15,Currency!$A$1:$A$20,0),MATCH(V15,Currency!$A$1:$E$1,0))))*(Inflation!$B$23/(VLOOKUP(U15,Inflation!$A$1:$B$23,2,FALSE))) -> -18.164329 | Z15: Germany | AA15: Solar, Table 3
A16: 355 | B16: 0.05 | C16: 3.3665374 | D16: EU | F16: 400 | G16: 0.08 | H16: 10.558872 | I16: in Austria | K16: 456 | L16: 2015 | M16: GBP | N16: 0.37 | O16: 11 | P16: =O16*(1/(INDEX(Currency!$A$1:$E$20,MATCH(L16,Currency!$A$1:$A$20,0),MATCH(M16,Currency!$A$1:$E$1,0))))*(Inflation!$B$23/(VLOOKUP(L16,Inflation!$A$1:$B$23,2,FALSE))) -> 15.458856 | Q16: UK | R16: Offshore wind, Moderate progress | T16: 347 | U16: 2009 | V16: EUR | W16: 0.011 | X16: -5 | Y16: =X16*(1/(INDEX(Currency!$A$1:$E$20,MATCH(U16,Currency!$A$1:$A$20,0),MATCH(V16,Currency!$A$1:$E$1,0))))*(Inflation!$B$23/(VLOOKUP(U16,Inflation!$A$1:$B$23,2,FALSE))) -> -5.6206592 | Z16: Germany | AA16: Solar, Table 3
A17: 355 | B17: 0.1 | C17: 4.1415382 | D17: EU | F17: 400 | G17: 0.1 | H17: 11.276465 | I17: in Austria | K17: 456 | L17: 2015 | M17: GBP | N17: 0.47 | O17: 11.2 | P17: =O17*(1/(INDEX(Currency!$A$1:$E$20,MATCH(L17,Currency!$A$1:$A$20,0),MATCH(M17,Currency!$A$1:$E$1,0))))*(Inflation!$B$23/(VLOOKUP(L17,Inflation!$A$1:$B$23,2,FALSE))) -> 15.739926 | Q17: UK | R17: Offshore wind, Moderate progress | T17: 347 | U17: 2010 | V17: EUR | W17: 0.021 | X17: -5 | Y17: =X17*(1/(INDEX(Currency!$A$1:$E$20,MATCH(U17,Currency!$A$1:$A$20,0),MATCH(V17,Currency!$A$1:$E$1,0))))*(Inflation!$B$23/(VLOOKUP(U17,Inflation!$A$1:$B$23,2,FALSE))) -> -5.5059395 | Z17: Germany | AA17: Solar, Table 3
A18: 355 | B18: 0.15 | C18: 4.2235488 | D18: EU | F18: 400 | G18: 0.12 | H18: 11.686519 | I18: in Austria | K18: 456 | L18: 2015 | M18: GBP | N18: 0.265 | O18: 6.6 | P18: =O18*(1/(INDEX(Currency!$A$1:$E$20,MATCH(L18,Currency!$A$1:$A$20,0),MATCH(M18,Currency!$A$1:$E$1,0))))*(Inflation!$B$23/(VLOOKUP(L18,Inflation!$A$1:$B$23,2,FALSE))) -> 9.2753136 | Q18: UK | R18: Offshore wind, Fast progress | T18: 347 | U18: 2011 | V18: EUR | W18: 0.033 | X18: -5 | Y18: =X18*(1/(INDEX(Currency!$A$1:$E$20,MATCH(U18,Currency!$A$1:$A$20,0),MATCH(V18,Currency!$A$1:$E$1,0))))*(Inflation!$B$23/(VLOOKUP(U18,Inflation!$A$1:$B$23,2,FALSE))) -> -5.3404211 | Z18: Germany | AA18: Solar, Table 3
A19: 355 | B19: 0.2 | C19: 4.2368755 | D19: EU | F19: 400 | G19: 0.14 | H19: 12.096572 | I19: in Austria | K19: 456 | L19: 2015 | M19: GBP | N19: 0.279 | O19: 7.4 | P19: =O19*(1/(INDEX(Currency!$A$1:$E$20,MATCH(L19,Currency!$A$1:$A$20,0),MATCH(M19,Currency!$A$1:$E$1,0))))*(Inflation!$B$23/(VLOOKUP(L19,Inflation!$A$1:$B$23,2,FALSE))) -> 10.399594 | Q19: UK | R19: Offshore wind, Fast progress | T19: 347 | U19: 2012 | V19: EUR | W19: 0.045 | X19: -2 | Y19: =X19*(1/(INDEX(Currency!$A$1:$E$20,MATCH(U19,Currency!$A$1:$A$20,0),MATCH(V19,Currency!$A$1:$E$1,0))))*(Inflation!$B$23/(VLOOKUP(U19,Inflation!$A$1:$B$23,2,FALSE))) -> -2.0812328 | Z19: Germany | AA19: Solar, Table 3
A20: 355 | B20: 0.25 | C20: 4.663331 | D20: EU | F20: 400 | G20: 0.16 | H20: 12.301598 | I20: in Austria | K20: 456 | L20: 2015 | M20: GBP | N20: 0.355 | O20: 7.7 | P20: =O20*(1/(INDEX(Currency!$A$1:$E$20,MATCH(L20,Currency!$A$1:$A$20,0),MATCH(M20,Currency!$A$1:$E$1,0))))*(Inflation!$B$23/(VLOOKUP(L20,Inflation!$A$1:$B$23,2,FALSE))) -> 10.821199 | Q20: UK | R20: Offshore wind, Fast progress | T20: 347 | U20: 2013 | V20: EUR | W20: 0.1 | X20: 8.4 | Y20: =X20*(1/(INDEX(Currency!$A$1:$E$20,MATCH(U20,Currency!$A$1:$A$20,0),MATCH(V20,Currency!$A$1:$E$1,0))))*(Inflation!$B$23/(VLOOKUP(U20,Inflation!$A$1:$B$23,2,FALSE))) -> 8.6111189 | Z20: Germany | AA20: Wind, Fig 9
A21: 355 | B21: 0.3 | C21: 5.0200773 | D21: EU | F21: 400 | G21: 0.18 | H21: 12.506625 | I21: in Austria | K21: 456 | L21: 2015 | M21: GBP | N21: 0.37 | O21: 7.6 | P21: =O21*(1/(INDEX(Currency!$A$1:$E$20,MATCH(L21,Currency!$A$1:$A$20,0),MATCH(M21,Currency!$A$1:$E$1,0))))*(Inflation!$B$23/(VLOOKUP(L21,Inflation!$A$1:$B$23,2,FALSE))) -> 10.680664 | Q21: UK | R21: Offshore wind, Fast progress | T21: 347 | U21: 2013 | V21: EUR | W21: 0.2 | X21: 13.9 | Y21: =X21*(1/(INDEX(Currency!$A$1:$E$20,MATCH(U21,Currency!$A$1:$A$20,0),MATCH(V21,Currency!$A$1:$E$1,0))))*(Inflation!$B$23/(VLOOKUP(U21,Inflation!$A$1:$B$23,2,FALSE))) -> 14.249352 | Z21: Germany | AA21: Wind, Fig 9
A22: 355 | B22: 0.35 | C22: 4.9001367 | D22: EU | F22: 400 | G22: 0.02 | H22: 9.2261989 | I22: in Belgium | K22: 456 | L22: 2015 | M22: GBP | N22: 0.415 | O22: 6.5 | P22: =O22*(1/(INDEX(Currency!$A$1:$E$20,MATCH(L22,Currency!$A$1:$A$20,0),MATCH(M22,Currency!$A$1:$E$1,0))))*(Inflation!$B$23/(VLOOKUP(L22,Inflation!$A$1:$B$23,2,FALSE))) -> 9.1347785 | Q22: UK | R22: Offshore wind, Fast progress | T22: 347 | U22: 2013 | V22: EUR | W22: 0.3 | X22: 16.7 | Y22: =X22*(1/(INDEX(Currency!$A$1:$E$20,MATCH(U22,Currency!$A$1:$A$20,0),MATCH(V22,Currency!$A$1:$E$1,0))))*(Inflation!$B$23/(VLOOKUP(U22,Inflation!$A$1:$B$23,2,FALSE))) -> 17.119725 | Z22: Germany | AA22: Wind, Fig 9
A23: 355 | B23: 0.4 | C23: 5.3891253 | D23: EU | F23: 400 | G23: 0.04 | H23: 9.2261989 | I23: in Belgium | K23: 456 | L23: 2015 | M23: GBP | N23: 0.46 | O23: 7.7 | P23: =O23*(1/(INDEX(Currency!$A$1:$E$20,MATCH(L23,Currency!$A$1:$A$20,0),MATCH(M23,Currency!$A$1:$E$1,0))))*(Inflation!$B$23/(VLOOKUP(L23,Inflation!$A$1:$B$23,2,FALSE))) -> 10.821199 | Q23: UK | R23: Offshore wind, Fast progress | T23: 347 | U23: 2013 | V23: EUR | W23: 0.1 | X23: 10.2 | Y23: =X23*(1/(INDEX(Currency!$A$1:$E$20,MATCH(U23,Currency!$A$1:$A$20,0),MATCH(V23,Currency!$A$1:$E$1,0))))*(Inflation!$B$23/(VLOOKUP(U23,Inflation!$A$1:$B$23,2,FALSE))) -> 10.456359 | Z23: Germany | AA23: Wind, Fig 19
A24: 403 | D24: In UK | F24: 400 | G24: 0.06 | H24: 10.763899 | I24: in Belgium | K24: 456 | L24: 2015 | M24: GBP | N24: 0.46 | O24: 8.2 | P24: =O24*(1/(INDEX(Currency!$A$1:$E$20,MATCH(L24,Currency!$A$1:$A$20,0),MATCH(M24,Currency!$A$1:$E$1,0))))*(Inflation!$B$23/(VLOOKUP(L24,Inflation!$A$1:$B$23,2,FALSE))) -> 11.523874 | Q24: UK | R24: Offshore wind, Fast progress | T24: 347 | U24: 2013 | V24: EUR | W24: 0.2 | X24: 19.4 | Y24: =X24*(1/(INDEX(Currency!$A$1:$E$20,MATCH(U24,Currency!$A$1:$A$20,0),MATCH(V24,Currency!$A$1:$E$1,0))))*(Inflation!$B$23/(VLOOKUP(U24,Inflation!$A$1:$B$23,2,FALSE))) -> 19.887584 | Z24: Germany | AA24: Wind, Fig 19
A25: 403 | D25: In UK | F25: 400 | G25: 0.08 | H25: 11.584005 | I25: in Belgium | K25: 456 | L25: 2015 | M25: GBP | N25: 0.538 | O25: 11.1 | P25: =O25*(1/(INDEX(Currency!$A$1:$E$20,MATCH(L25,Currency!$A$1:$A$20,0),MATCH(M25,Currency!$A$1:$E$1,0))))*(Inflation!$B$23/(VLOOKUP(L25,Inflation!$A$1:$B$23,2,FALSE))) -> 15.599391 | Q25: UK | R25: Offshore wind, Fast progress | T25: 347 | U25: 2013 | V25: EUR | W25: 0.3 | X25: 24.1 | Y25: =X25*(1/(INDEX(Currency!$A$1:$E$20,MATCH(U25,Currency!$A$1:$A$20,0),MATCH(V25,Currency!$A$1:$E$1,0))))*(Inflation!$B$23/(VLOOKUP(U25,Inflation!$A$1:$B$23,2,FALSE))) -> 24.70571 | Z25: Germany | AA25: Wind, Fig 19
A26: 403 | D26: In UK | F26: 400 | G26: 0.1 | H26: 12.096572 | I26: in Belgium | K26: 456 | L26: 2015 | M26: GBP | N26: 0.538 | O26: 11.4 | P26: =O26*(1/(INDEX(Currency!$A$1:$E$20,MATCH(L26,Currency!$A$1:$A$20,0),MATCH(M26,Currency!$A$1:$E$1,0))))*(Inflation!$B$23/(VLOOKUP(L26,Inflation!$A$1:$B$23,2,FALSE))) -> 16.020996 | Q26: UK | R26: Offshore wind, Fast progress | T26: 355 | U26: 2013 | V26: EUR | W26: 0.05 | X26: 15.2 | Y26: =X26*(1/(INDEX(Currency!$A$1:$E$20,MATCH(U26,Currency!$A$1:$A$20,0),MATCH(V26,Currency!$A$1:$E$1,0))))*(Inflation!$B$23/(VLOOKUP(U26,Inflation!$A$1:$B$23,2,FALSE))) -> 15.582025 | Z26: Germany | AA26: Wind, Fig 10
A27: 403 | D27: In UK | F27: 400 | G27: 0.12 | H27: 12.404112 | I27: in Belgium | K27: 456 | L27: 2015 | M27: GBP | N27: 0.56 | O27: 18.6 | P27: =O27*(1/(INDEX(Currency!$A$1:$E$20,MATCH(L27,Currency!$A$1:$A$20,0),MATCH(M27,Currency!$A$1:$E$1,0))))*(Inflation!$B$23/(VLOOKUP(L27,Inflation!$A$1:$B$23,2,FALSE))) -> 26.13952 | Q27: UK | R27: Offshore wind, Fast progress | T27: 355 | U27: 2013 | V27: EUR | W27: 0.1 | X27: 18.7 | Y27: =X27*(1/(INDEX(Currency!$A$1:$E$20,MATCH(U27,Currency!$A$1:$A$20,0),MATCH(V27,Currency!$A$1:$E$1,0))))*(Inflation!$B$23/(VLOOKUP(U27,Inflation!$A$1:$B$23,2,FALSE))) -> 19.169991 | Z27: Germany | AA27: Wind, Fig 10
A28: 403 | D28: In UK | F28: 400 | G28: 0.14 | H28: 12.711652 | I28: in Belgium | K28: 456 | L28: 2015 | M28: GBP | N28: 0.602 | O28: 17.6 | P28: =O28*(1/(INDEX(Currency!$A$1:$E$20,MATCH(L28,Currency!$A$1:$A$20,0),MATCH(M28,Currency!$A$1:$E$1,0))))*(Inflation!$B$23/(VLOOKUP(L28,Inflation!$A$1:$B$23,2,FALSE))) -> 24.73417 | Q28: UK | R28: Offshore wind, Fast progress | T28: 355 | U28: 2013 | V28: EUR | W28: 0.15 | X28: 21.8 | Y28: =X28*(1/(INDEX(Currency!$A$1:$E$20,MATCH(U28,Currency!$A$1:$A$20,0),MATCH(V28,Currency!$A$1:$E$1,0))))*(Inflation!$B$23/(VLOOKUP(U28,Inflation!$A$1:$B$23,2,FALSE))) -> 22.347904 | Z28: Germany | AA28: Wind, Fig 10
A29: 403 | D29: In UK | F29: 400 | G29: 0.16 | H29: 12.814165 | I29: in Belgium | K29: 456 | L29: 2015 | M29: GBP | N29: 0.602 | O29: 22.7 | P29: =O29*(1/(INDEX(Currency!$A$1:$E$20,MATCH(L29,Currency!$A$1:$A$20,0),MATCH(M29,Currency!$A$1:$E$1,0))))*(Inflation!$B$23/(VLOOKUP(L29,Inflation!$A$1:$B$23,2,FALSE))) -> 31.901457 | Q29: UK | R29: Offshore wind, Fast progress | T29: 355 | U29: 2013 | V29: EUR | W29: 0.2 | X29: 24.7 | Y29: =X29*(1/(INDEX(Currency!$A$1:$E$20,MATCH(U29,Currency!$A$1:$A$20,0),MATCH(V29,Currency!$A$1:$E$1,0))))*(Inflation!$B$23/(VLOOKUP(U29,Inflation!$A$1:$B$23,2,FALSE))) -> 25.32079 | Z29: Germany | AA29: Wind, Fig 10
A30: 403 | D30: In UK | F30: 400 | G30: 0.18 | H30: 13.019192 | I30: in Belgium | K30: 456 | L30: 2015 | M30: GBP | N30: 0.452 | O30: 5.5 | P30: =O30*(1/(INDEX(Currency!$A$1:$E$20,MATCH(L30,Currency!$A$1:$A$20,0),MATCH(M30,Currency!$A$1:$E$1,0))))*(Inflation!$B$23/(VLOOKUP(L30,Inflation!$A$1:$B$23,2,FALSE))) -> 7.729428 | Q30: UK | R30: Offshore wind, Maximum progress | T30: 355 | U30: 2013 | V30: EUR | W30: 0.25 | X30: 26.8 | Y30: =X30*(1/(INDEX(Currency!$A$1:$E$20,MATCH(U30,Currency!$A$1:$A$20,0),MATCH(V30,Currency!$A$1:$E$1,0))))*(Inflation!$B$23/(VLOOKUP(U30,Inflation!$A$1:$B$23,2,FALSE))) -> 27.47357 | Z30: Germany | AA30: Wind, Fig 10
A31: 403 | D31: In UK | F31: 400 | G31: 0.02 | H31: 8.4060923 | I31: in Belgium | K31: 456 | L31: 2015 | M31: GBP | N31: 0.453 | O31: 5.6 | P31: =O31*(1/(INDEX(Currency!$A$1:$E$20,MATCH(L31,Currency!$A$1:$A$20,0),MATCH(M31,Currency!$A$1:$E$1,0))))*(Inflation!$B$23/(VLOOKUP(L31,Inflation!$A$1:$B$23,2,FALSE))) -> 7.869963 | Q31: UK | R31: Offshore wind, Maximum progress | T31: 355 | U31: 2013 | V31: EUR | W31: 0.3 | X31: 31.7 | Y31: =X31*(1/(INDEX(Currency!$A$1:$E$20,MATCH(U31,Currency!$A$1:$A$20,0),MATCH(V31,Currency!$A$1:$E$1,0))))*(Inflation!$B$23/(VLOOKUP(U31,Inflation!$A$1:$B$23,2,FALSE))) -> 32.496723 | Z31: Germany | AA31: Wind, Fig 10
A32: 403 | D32: In UK | F32: 400 | G32: 0.04 | H32: 8.4060923 | I32: in Belgium | K32: 456 | L32: 2015 | M32: GBP | N32: 0.528 | O32: 6.7 | P32: =O32*(1/(INDEX(Currency!$A$1:$E$20,MATCH(L32,Currency!$A$1:$A$20,0),MATCH(M32,Currency!$A$1:$E$1,0))))*(Inflation!$B$23/(VLOOKUP(L32,Inflation!$A$1:$B$23,2,FALSE))) -> 9.4158486 | Q32: UK | R32: Offshore wind, Maximum progress | T32: 355 | U32: 2013 | V32: EUR | W32: 0.35 | X32: 36.7 | Y32: =X32*(1/(INDEX(Currency!$A$1:$E$20,MATCH(U32,Currency!$A$1:$A$20,0),MATCH(V32,Currency!$A$1:$E$1,0))))*(Inflation!$B$23/(VLOOKUP(U32,Inflation!$A$1:$B$23,2,FALSE))) -> 37.622389 | Z32: Germany | AA32: Wind, Fig 10
A33: 403 | D33: In UK | F33: 400 | G33: 0.06 | H33: 10.046305 | I33: in Belgium | K33: 456 | L33: 2015 | M33: GBP | N33: 0.53 | O33: 6.7 | P33: =O33*(1/(INDEX(Currency!$A$1:$E$20,MATCH(L33,Currency!$A$1:$A$20,0),MATCH(M33,Currency!$A$1:$E$1,0))))*(Inflation!$B$23/(VLOOKUP(L33,Inflation!$A$1:$B$23,2,FALSE))) -> 9.4158486 | Q33: UK | R33: Offshore wind, Maximum progress | T33: 355 | U33: 2013 | V33: EUR | W33: 0.4 | X33: 44.7 | Y33: =X33*(1/(INDEX(Currency!$A$1:$E$20,MATCH(U33,Currency!$A$1:$A$20,0),MATCH(V33,Currency!$A$1:$E$1,0))))*(Inflation!$B$23/(VLOOKUP(U33,Inflation!$A$1:$B$23,2,FALSE))) -> 45.823454 | Z33: Germany | AA33: Wind, Fig 10
A34: 403 | D34: In UK | F34: 400 | G34: 0.08 | H34: 10.046305 | I34: in Belgium | K34: 456 | L34: 2015 | M34: GBP | N34: 0.589 | O34: 7.8 | P34: =O34*(1/(INDEX(Currency!$A$1:$E$20,MATCH(L34,Currency!$A$1:$A$20,0),MATCH(M34,Currency!$A$1:$E$1,0))))*(Inflation!$B$23/(VLOOKUP(L34,Inflation!$A$1:$B$23,2,FALSE))) -> 10.961734 | Q34: UK | R34: Offshore wind, Maximum progress | T34: 355 | U34: 2013 | V34: EUR | W34: 0.05 | X34: 13.5 | Y34: =X34*(1/(INDEX(Currency!$A$1:$E$20,MATCH(U34,Currency!$A$1:$A$20,0),MATCH(V34,Currency!$A$1:$E$1,0))))*(Inflation!$B$23/(VLOOKUP(U34,Inflation!$A$1:$B$23,2,FALSE))) -> 13.839298 | Z34: Germany | AA34: Solar, Fig 10
A35: 403 | D35: In UK | F35: 400 | G35: 0.1 | H35: 10.046305 | I35: in Belgium | K35: 456 | L35: 2015 | M35: GBP | N35: 0.589 | O35: 7.4 | P35: =O35*(1/(INDEX(Currency!$A$1:$E$20,MATCH(L35,Currency!$A$1:$A$20,0),MATCH(M35,Currency!$A$1:$E$1,0))))*(Inflation!$B$23/(VLOOKUP(L35,Inflation!$A$1:$B$23,2,FALSE))) -> 10.399594 | Q35: UK | R35: Offshore wind, Maximum progress | T35: 355 | U35: 2013 | V35: EUR | W35: 0.1 | X35: 27.4 | Y35: =X35*(1/(INDEX(Currency!$A$1:$E$20,MATCH(U35,Currency!$A$1:$A$20,0),MATCH(V35,Currency!$A$1:$E$1,0))))*(Inflation!$B$23/(VLOOKUP(U35,Inflation!$A$1:$B$23,2,FALSE))) -> 28.08865 | Z35: Germany | AA35: Solar, Fig 10
A36: 403 | D36: In UK | F36: 400 | G36: 0.12 | H36: 10.046305 | I36: in Belgium | K36: 403/455 | L36: 2015 | M36: GBP | N36: 0.362 | O36: 23 | P36: =O36*(1/(INDEX(Currency!$A$1:$E$20,MATCH(L36,Currency!$A$1:$A$20,0),MATCH(M36,Currency!$A$1:$E$1,0))))*(Inflation!$B$23/(VLOOKUP(L36,Inflation!$A$1:$B$23,2,FALSE))) -> 32.323062 | Q36: UK | R36: Onshore wind, CCC 2015 | T36: 355 | U36: 2013 | V36: EUR | W36: 0.15 | X36: 33.4 | Y36: =X36*(1/(INDEX(Currency!$A$1:$E$20,MATCH(U36,Currency!$A$1:$A$20,0),MATCH(V36,Currency!$A$1:$E$1,0))))*(Inflation!$B$23/(VLOOKUP(U36,Inflation!$A$1:$B$23,2,FALSE))) -> 34.239449 | Z36: Germany | AA36: Solar, Fig 10
A37: 403 | D37: In UK | F37: 400 | G37: 0.14 | H37: 10.456359 | I37: in Belgium | K37: 403/455 | L37: 2015 | M37: GBP | N37: 0.364 | O37: 13.5 | P37: =O37*(1/(INDEX(Currency!$A$1:$E$20,MATCH(L37,Currency!$A$1:$A$20,0),MATCH(M37,Currency!$A$1:$E$1,0))))*(Inflation!$B$23/(VLOOKUP(L37,Inflation!$A$1:$B$23,2,FALSE))) -> 18.972232 | Q37: UK | R37: Onshore wind, CCC 2015 | T37: 355 | U37: 2013 | V37: EUR | W37: 0.2 | X37: 49.2 | Y37: =X37*(1/(INDEX(Currency!$A$1:$E$20,MATCH(U37,Currency!$A$1:$A$20,0),MATCH(V37,Currency!$A$1:$E$1,0))))*(Inflation!$B$23/(VLOOKUP(U37,Inflation!$A$1:$B$23,2,FALSE))) -> 50.436554 | Z37: Germany | AA37: Solar, Fig 10
A38: 403 | D38: In UK | F38: 400 | G38: 0.16 | H38: 10.866412 | I38: in Belgium | K38: 403/455 | L38: 2015 | M38: GBP | N38: 0.364 | O38: 6.3 | P38: =O38*(1/(INDEX(Currency!$A$1:$E$20,MATCH(L38,Currency!$A$1:$A$20,0),MATCH(M38,Currency!$A$1:$E$1,0))))*(Inflation!$B$23/(VLOOKUP(L38,Inflation!$A$1:$B$23,2,FALSE))) -> 8.8537084 | Q38: UK | R38: Onshore wind, CCC 2015 | T38: 355 | U38: 2013 | V38: EUR | W38: 0.25 | X38: 100 | Y38: =X38*(1/(INDEX(Currency!$A$1:$E$20,MATCH(U38,Currency!$A$1:$A$20,0),MATCH(V38,Currency!$A$1:$E$1,0))))*(Inflation!$B$23/(VLOOKUP(U38,Inflation!$A$1:$B$23,2,FALSE))) -> 102.51332 | Z38: Germany | AA38: Solar, Fig 10
A39: 403 | D39: In UK | F39: 400 | G39: 0.18 | H39: 11.071439 | I39: in Belgium | K39: 403/455 | L39: 2015 | M39: GBP | N39: 0.471 | O39: 36.8 | P39: =O39*(1/(INDEX(Currency!$A$1:$E$20,MATCH(L39,Currency!$A$1:$A$20,0),MATCH(M39,Currency!$A$1:$E$1,0))))*(Inflation!$B$23/(VLOOKUP(L39,Inflation!$A$1:$B$23,2,FALSE))) -> 51.7169 | Q39: UK | R39: Onshore wind, CCC 2015 | T39: 457 | U39: 2015 | V39: EUR | W39: 0.001 | X39: 2.7 | Y39: =X39*(1/(INDEX(Currency!$A$1:$E$20,MATCH(U39,Currency!$A$1:$A$20,0),MATCH(V39,Currency!$A$1:$E$1,0))))*(Inflation!$B$23/(VLOOKUP(U39,Inflation!$A$1:$B$23,2,FALSE))) -> 2.75319 | Z39: Various | AA39: Wind, Fig 13
A40: 403 | D40: In UK | F40: 400 | G40: 0.02 | H40: 10.866412 | I40: in Czech Republic | K40: 403/455 | L40: 2015 | M40: GBP | N40: 0.48 | O40: 35.4 | P40: =O40*(1/(INDEX(Currency!$A$1:$E$20,MATCH(L40,Currency!$A$1:$A$20,0),MATCH(M40,Currency!$A$1:$E$1,0))))*(Inflation!$B$23/(VLOOKUP(L40,Inflation!$A$1:$B$23,2,FALSE))) -> 49.749409 | Q40: UK | R40: Onshore wind, CCC 2015 | T40: 457 | U40: 2015 | V40: EUR | W40: 0.002 | X40: -6.7 | Y40: =X40*(1/(INDEX(Currency!$A$1:$E$20,MATCH(U40,Currency!$A$1:$A$20,0),MATCH(V40,Currency!$A$1:$E$1,0))))*(Inflation!$B$23/(VLOOKUP(U40,Inflation!$A$1:$B$23,2,FALSE))) -> -6.83199 | Z40: Various | AA40: Wind, Fig 13
...

Sheet Inflation
A1: Year | B1: Inflation
A2: 1996 | E2: Note: Data from the Office for National Statistics, document 'CPI-Consumer Prices Index (COICOP)'
A3: 1997 | E3: http://www.ons.gov.uk/ons/rel/cpi/consumer-price-indices/october-2015/index.html
A4: 1998
A5: 1999 | E5: original data: | L5: November 2015 GDP deflator values from:
A6: 2000 | B6: 74.73 | E6: Jan 1996 | G6: 86.8 | L6: https://www.gov.uk/government/statistics/gdp-deflators-at-market-prices-and-money-gdp-november-2015-the-autumn-statement
A7: 2001 | B7: 76.37 | E7: Feb 1996 | G7: 87.2 | L7: Year | M7: Index
A8: 2002 | B8: 77.96 | E8: Mar 1996 | G8: 87.5 | L8: 1955 | M8: 4.434
A9: 2003 | B9: 79.49 | E9: Apr 1996 | G9: 88 | L9: 1956 | M9: 4.734
A10: 2004 | B10: 81.09 | E10: May 1996 | G10: 88.3 | L10: 1957 | M10: 4.922
A11: 2005 | B11: 82.85 | E11: Jun 1996 | G11: 88.4 | L11: 1958 | M11: 5.099 | Q11: Eurozone harmonized index of consumer prices from:
A12: 2006 | B12: 84.67 | E12: Jul 1996 | G12: 87.8 | L12: 1959 | M12: 5.131 | Q12: https://ec.europa.eu/eurostat/web/hicp/data/database
A13: 2007 | B13: 86.65 | E13: Aug 1996 | G13: 88.3 | L13: 1960 | M13: 5.179
A14: 2008 | B14: 89.82 | E14: Sep 1996 | G14: 88.7 | L14: 1961 | M14: 5.355 | Q14: 2000 | R14: 74.73
A15: 2009 | B15: 90.71 | E15: Oct 1996 | G15: 88.7 | L15: 1962 | M15: 5.536 | Q15: 2001 | R15: 76.37
A16: 2010 | B16: 92.6 | E16: Nov 1996 | G16: 88.7 | L16: 1963 | M16: 5.622 | Q16: 2002 | R16: 77.96
A17: 2011 | B17: 95.47 | E17: Dec 1996 | G17: 89 | L17: 1964 | M17: 5.808 | Q17: 2003 | R17: 79.49
A18: 2012 | B18: 97.99 | E18: Jan 1997 | G18: 88.6 | L18: 1965 | M18: 6.134 | Q18: 2004 | R18: 81.09
A19: 2013 | B19: 99.47 | E19: Feb 1997 | G19: 88.8 | L19: 1966 | M19: 6.44 | Q19: 2005 | R19: 82.85
A20: 2014 | B20: 100.01 | E20: Mar 1997 | G20: 89 | L20: 1967 | M20: 6.618 | Q20: 2006 | R20: 84.67
A21: 2015 | B21: 100 | E21: Apr 1997 | G21: 89.4 | L21: 1968 | M21: 6.876 | Q21: 2007 | R21: 86.65
A22: 2016 | B22: 100.25 | E22: May 1997 | G22: 89.6 | L22: 1969 | M22: 7.29 | Q22: 2008 | R22: 89.82
A23: 2017 | B23: 101.97 | E23: Jun 1997 | G23: 89.8 | L23: 1970 | M23: 7.961 | Q23: 2009 | R23: 90.71
A24: 2018 | B24: 104.13 | E24: Jul 1997 | G24: 89.5 | L24: 1971 | M24: 8.6 | Q24: 2010 | R24: 92.6
E25: Aug 1997 | G25: 90 | L25: 1972 | M25: 9.225 | Q25: 2011 | R25: 95.47
E26: Sep 1997 | G26: 90.3 | L26: 1973 | M26: 10.006 | Q26: 2012 | R26: 97.99
E27: Oct 1997 | G27: 90.3 | L27: 1974 | M27: 11.514 | Q27: 2013 | R27: 99.47
E28: Nov 1997 | G28: 90.4 | L28: 1975 | M28: 14.497 | Q28: 2014 | R28: 100.01
E29: Dec 1997 | G29: 90.5 | L29: 1976 | M29: 16.658 | Q29: 2015 | R29: 100
E30: Jan 1998 | G30: 89.9 | L30: 1977 | M30: 18.92 | Q30: 2016 | R30: 100.25
E31: Feb 1998 | G31: 90.3 | L31: 1978 | M31: 21.101 | Q31: 2017 | R31: 101.97
E32: Mar 1998 | G32: 90.5 | L32: 1979 | M32: 24.086 | Q32: 2018 | R32: 104.13
E33: Apr 1998 | G33: 91 | L33: 1980 | M33: 28.896
E34: May 1998 | G34: 91.5 | L34: 1981 | M34: 32.238
E35: Jun 1998 | G35: 91.3 | L35: 1982 | M35: 34.603
E36: Jul 1998 | G36: 90.8 | L36: 1983 | M36: 36.381
E37: Aug 1998 | G37: 91.2 | L37: 1984 | M37: 38.218
E38: Sep 1998 | G38: 91.6 | L38: 1985 | M38: 40.415
E39: Oct 1998 | G39: 91.6 | L39: 1986 | M39: 42.169
E40: Nov 1998 | G40: 91.7 | L40: 1987 | M40: 44.365
...

Sheet Currency
A1: Year | B1: USD | C1: EUR | D1: CAD | E1: GBP
A2: 2000 | B2: 0.92260382 | C2: 1 | D2: 1.3695652 | E2: 0.60893923
A3: 2001 | B3: 0.89513272 | C3: 1 | D3: 1.3861503 | E3: 0.62161994
A4: 2002 | B4: 0.94506254 | C4: 1 | D4: 1.4840028 | E4: 0.62857502
A5: 2003 | B5: 1.1312258 | C5: 1 | D5: 1.5825263 | E5: 0.69175429
A6: 2004 | B6: 1.2431644 | C6: 1 | D6: 1.6168668 | E6: 0.67847208 | H6: Note: Exchange rate data is "spot exchange rate against £ sterling" from Bank of England "Statistical Interactive Database "
A7: 2005 | B7: 1.2433522 | C7: 1 | D7: 1.5071433 | E7: 0.68357372 | H7: http://www.bankofengland.co.uk/mfsd/iadb/index.asp?Travel=NIxIRx&levels=2&XNotes=Y&A3790XNode3790.x=2&A3790XNode3790.y=7&Nodes=&SectionRequired=I&HideNums=-1&ExtraInfo=true#BM
A8: 2006 | B8: 1.2563054 | C8: 1 | D8: 1.4246762 | E8: 0.68166326
A9: 2007 | B9: 1.3695875 | C9: 1 | D9: 1.4684315 | E9: 0.68404132 | H9: (Annual average exchange rates)
A10: 2008 | B10: 1.471878 | C10: 1 | D10: 1.5587067 | E10: 0.79440737
A11: 2009 | B11: 1.3945518 | C11: 1 | D11: 1.5846168 | E11: 0.89023413
A12: 2010 | B12: 1.3254458 | C12: 1 | D12: 1.3653121 | E12: 0.85733882
A13: 2011 | B13: 1.390648 | C13: 1 | D13: 1.3760736 | E13: 0.86752841
A14: 2012 | B14: 1.2848342 | C14: 1 | D14: 1.2838616 | E14: 0.81056983
A15: 2013 | B15: 1.3284647 | C15: 1 | D15: 1.3688859 | E15: 0.84918478
A16: 2014 | B16: 1.3276126 | C16: 1 | D16: 1.4654742 | E16: 0.80573685
A17: 2015 | B17: 1.1091278 | C17: 1 | D17: 1.418662 | E17: 0.7255841
A18: 2016 | B18: 1.1070056 | C18: 1 | D18: 1.4671789 | E18: 0.81746097
A19: 2017 | B19: 1.1292386 | C19: 1 | D19: 1.4646456 | E19: 0.87619381
A20: 2018 | B20: 1.1945807 | C20: 1 | D20: 1.5376754 | E20: 0.88375549

Sheet CPI USA
A1: FRED Graph Observations
A2: Federal Reserve Economic Data
A3: Link: https://fred.stlouisfed.org
A4: Help: https://fredhelp.stlouisfed.org
A5: Economic Research Division
A6: Federal Reserve Bank of St. Louis
A8: CPALTT01USA661S | B8: Consumer Price Indices (CPIs, HICPs), COICOP 1999: Consumer Price Index: Total for United States, Index 2015=100, Annual, Seasonally Adjusted
A10: Frequency: Annual
A11: observation_date | B11: CPALTT01USA661S | D11: Exchange Rate in 2017
A12: 20090 | B12: 11.29666 | D12: 1 euro = | E12: 1.1304 | F12: USD
A13: 20455 | B13: 11.46894
A14: 20821 | B14: 11.85217
A15: 21186 | B15: 12.17564
A16: 21551 | B16: 12.2987
A17: 21916 | B17: 12.47801
A18: 22282 | B18: 12.61161
A19: 22647 | B19: 12.7628
A20: 23012 | B20: 12.92101
A21: 23377 | B21: 13.08626
A22: 23743 | B22: 13.2937
A23: 24108 | B23: 13.69452
A24: 24473 | B24: 14.07424
... A80: 44927 | B80: 128.5569

Sheet OP RES COSTS
A1: Operating reserve Costs
A2: ID | B2: Penetration level | C2: 2017 €/MWh | D2: Region | E2: 2023 USD / MWh | F2: LCOE Solar | G2: Operating Reserve Costs as a % LCOE) | H2: LCOE Solar + Storage | J2: LCOE Wind (Onshore)
A3: 17 | B3: 0.4 | C3: 26.232572 | D3: n/a | E3: =C3*('CPI USA'!$E$12)*('CPI USA'!$B$80/'CPI USA'!$B$74) -> 36.861224 | F3: 23.22 | G3: =E3/$F$3 -> 1.5874773 | H3: 36.27 | J3: 31.07
A4: 17 | B4: 0.8 | C4: 17.657365 | D4: n/a | E4: =C4*('CPI USA'!$E$12)*('CPI USA'!$B$80/'CPI USA'!$B$74) -> 24.8116 | F4: 23.22 | G4: =E4/$F$3 -> 1.0685444
A5: 50 | B5: 0.04 | C5: 0.034407373 | D5: UK | E5: =C5*('CPI USA'!$E$12)*('CPI USA'!$B$80/'CPI USA'!$B$74) -> 0.04834821 | F5: 23.22 | G5: =E5/$F$3 -> 0.0020821796
A6: 50 | B6: 0.08 | C6: 0.13762949 | D6: UK | E6: =C6*('CPI USA'!$E$12)*('CPI USA'!$B$80/'CPI USA'!$B$74) -> 0.19339284 | F6: 23.22 | G6: =E6/$F$3 -> 0.0083287183
A7: 50 | B7: 0.12 | C7: 0.2580553 | D7: UK | E7: =C7*('CPI USA'!$E$12)*('CPI USA'!$B$80/'CPI USA'!$B$74) -> 0.36261158 | F7: 23.22 | G7: =E7/$F$3 -> 0.015616347
A8: 50 | B8: 0.16 | C8: 0.3784811 | D8: UK | E8: =C8*('CPI USA'!$E$12)*('CPI USA'!$B$80/'CPI USA'!$B$74) -> 0.53183031 | F8: 23.22 | G8: =E8/$F$3 -> 0.022903975
A9: 50 | B9: 0.2 | C9: 0.51611059 | D9: UK | E9: =C9*('CPI USA'!$E$12)*('CPI USA'!$B$80/'CPI USA'!$B$74) -> 0.72522315 | F9: 23.22 | G9: =E9/$F$3 -> 0.031232694
A10: 50 | B10: 0.04 | C10: 0.086018432 | D10: UK | E10: =C10*('CPI USA'!$E$12)*('CPI USA'!$B$80/'CPI USA'!$B$74) -> 0.12087053 | F10: 23.22 | G10: =E10/$F$3 -> 0.005205449
A11: 50 | B11: 0.08 | C11: 0.2580553 | D11: UK | E11: =C11*('CPI USA'!$E$12)*('CPI USA'!$B$80/'CPI USA'!$B$74) -> 0.36261158 | F11: 23.22 | G11: =E11/$F$3 -> 0.015616347
A12: 50 | B12: 0.12 | C12: 0.46449953 | D12: UK | E12: =C12*('CPI USA'!$E$12)*('CPI USA'!$B$80/'CPI USA'!$B$74) -> 0.65270084 | F12: 23.22 | G12: =E12/$F$3 -> 0.028109424
A13: 50 | B13: 0.16 | C13: 0.70535114 | D13: UK | E13: =C13*('CPI USA'!$E$12)*('CPI USA'!$B$80/'CPI USA'!$B$74) -> 0.99113831 | F13: 23.22 | G13: =E13/$F$3 -> 0.042684682
A14: 50 | B14: 0.2 | C14: 0.94620275 | D14: UK | E14: =C14*('CPI USA'!$E$12)*('CPI USA'!$B$80/'CPI USA'!$B$74) -> 1.3295758 | F14: 23.22 | G14: =E14/$F$3 -> 0.057259939
A15: 336 | B15: 0.33 | C15: 20.232619 | D15: California | E15: =C15*('CPI USA'!$E$12)*('CPI USA'!$B$80/'CPI USA'!$B$74) -> 28.430271 | F15: 23.22 | G15: =E15/$F$3 -> 1.2243872
... A23: 355 | B23: 0.4 | C23: 5.3891253 | D23: EU | E23: =C23*('CPI USA'!$E$12)*('CPI USA'!$B$80/'CPI USA'!$B$74) -> 7.5726374 | F23: 23.22 | G23: =E23/$F$3 -> 0.32612564
A24: 403 | D24: In UK | E24: =C24*('CPI USA'!$E$12)*('CPI USA'!$B$80/'CPI USA'!$B$74) -> 0
A25: 403 | D25: In UK | E25: =C25*('CPI USA'!$E$12)*('CPI USA'!$B$80/'CPI USA'!$B$74) -> 0
A26: 403 | D26: In UK | E26: =C26*('CPI USA'!$E$12)*('CPI USA'!$B$80/'CPI USA'!$B$74) -> 0
A27: 403 | D27: In UK | E27: =C27*('CPI USA'!$E$12)*('CPI USA'!$B$80/'CPI USA'!$B$74) -> 0
A28: 403 | D28: In UK | E28: =C28*('CPI USA'!$E$12)*('CPI USA'!$B$80/'CPI USA'!$B$74) -> 0
A29: 403 | D29: In UK | E29: =C29*('CPI USA'!$E$12)*('CPI USA'!$B$80/'CPI USA'!$B$74) -> 0
A30: 403 | D30: In UK | E30: =C30*('CPI USA'!$E$12)*('CPI USA'!$B$80/'CPI USA'!$B$74) -> 0
A31: 403 | D31: In UK | E31: =C31*('CPI USA'!$E$12)*('CPI USA'!$B$80/'CPI USA'!$B$74) -> 0
A32: 403 | D32: In UK | E32: =C32*('CPI USA'!$E$12)*('CPI USA'!$B$80/'CPI USA'!$B$74) -> 0
A33: 403 | D33: In UK | E33: =C33*('CPI USA'!$E$12)*('CPI USA'!$B$80/'CPI USA'!$B$74) -> 0
A34: 403 | D34: In UK | E34: =C34*('CPI USA'!$E$12)*('CPI USA'!$B$80/'CPI USA'!$B$74) -> 0
A35: 403 | D35: In UK | E35: =C35*('CPI USA'!$E$12)*('CPI USA'!$B$80/'CPI USA'!$B$74) -> 0
... A41: 403 | D41: In UK | E41: =C41*('CPI USA'!$E$12)*('CPI USA'!$B$80/'CPI USA'!$B$74) -> 0
A42: 413 | B42: 0.271 | C42: 6.4308535 | D42: In UK | E42: =C42*('CPI USA'!$E$12)*('CPI USA'!$B$80/'CPI USA'!$B$74) -> 9.0364428 | F42: 23.22 | G42: =E42/$F$3 -> 0.38916636
A43: 413 | B43: 0.326 | C43: 7.5741164 | D43: In UK | E43: =C43*('CPI USA'!$E$12)*('CPI USA'!$B$80/'CPI USA'!$B$74) -> 10.642921 | F43: 23.22 | G43: =E43/$F$3 -> 0.45835149
A44: 413 | B44: 0.417 | C44: 9.2890106 | D44: In UK | E44: =C44*('CPI USA'!$E$12)*('CPI USA'!$B$80/'CPI USA'!$B$74) -> 13.05264 | F44: 23.22 | G44: =E44/$F$3 -> 0.56212918
A45: 433 | B45: 0.05 | C45: 1.5737846 | D45: UK | E45: =C45*('CPI USA'!$E$12)*('CPI USA'!$B$80/'CPI USA'!$B$74) -> 2.211435 | F45: 23.22 | G45: =E45/$F$3 -> 0.095238371
A46: 433 | B46: 0.1 | C46: 2.6979164 | D46: UK | E46: =C46*('CPI USA'!$E$12)*('CPI USA'!$B$80/'CPI USA'!$B$74) -> 3.7910314 | F46: 23.22 | G46: =E46/$F$3 -> 0.16326578
A47: 433 | B47: 0.15 | C47: 3.2599824 | D47: UK | E47: =C47*('CPI USA'!$E$12)*('CPI USA'!$B$80/'CPI USA'!$B$74) -> 4.5808296 | F47: 23.22 | G47: =E47/$F$3 -> 0.19727948
A48: 433 | B48: 0.2 | C48: 3.8220483 | D48: UK | E48: =C48*('CPI USA'!$E$12)*('CPI USA'!$B$80/'CPI USA'!$B$74) -> 5.3706278 | F48: 23.22 | G48: =E48/$F$3 -> 0.23129319
A49: 433 | B49: 0.053 | C49: 3.1475692 | D49: US | E49: =C49*('CPI USA'!$E$12)*('CPI USA'!$B$80/'CPI USA'!$B$74) -> 4.42287 | F49: 23.22 | G49: =E49/$F$3 -> 0.19047674
A50: 433 | B50: 0.076 | C50: 4.271701 | D50: US | E50: =C50*('CPI USA'!$E$12)*('CPI USA'!$B$80/'CPI USA'!$B$74) -> 6.0024664 | F50: 23.22 | G50: =E50/$F$3 -> 0.25850415
A51: 433 | B51: 0.15 | C51: 2.5855033 | D51: US | E51: =C51*('CPI USA'!$E$12)*('CPI USA'!$B$80/'CPI USA'!$B$74) -> 3.6330717 | F51: 23.22 | G51: =E51/$F$3 -> 0.15646304
A52: 433 | B52: 0.2 | C52: 3.4848087 | D52: US | E52: =C52*('CPI USA'!$E$12)*('CPI USA'!$B$80/'CPI USA'!$B$74) -> 4.8967489 | F52: 23.22 | G52: =E52/$F$3 -> 0.21088496
...

Sheet Capacity Costs
A1: Capacity Costs
A2: ID | B2: Penetration level | C2: 2017 €/MWh | D2: Region | E2: Costs in Inflation adjusted 2023 USD
A3: 50 | B3: 0.2 | C3: 0.92899907 | D3: UK | E3: =C3*('CPI USA'!$E$12)*('CPI USA'!$B$80/'CPI USA'!$B$74) -> 1.3054017
A4: 400 | B4: 0.02 | C4: 6.1507992 | D4: in Austria | E4: =C4*('CPI USA'!$E$12)*('CPI USA'!$B$80/'CPI USA'!$B$74) -> 8.6429189
A5: 400 | B5: 0.04 | C5: 8.5086056 | D5: in Austria | E5: =C5*('CPI USA'!$E$12)*('CPI USA'!$B$80/'CPI USA'!$B$74) -> 11.956038
A6: 400 | B6: 0.06 | C6: 10.866412 | D6: in Austria | E6: =C6*('CPI USA'!$E$12)*('CPI USA'!$B$80/'CPI USA'!$B$74) -> 15.269157
A7: 400 | B7: 0.08 | C7: 11.994059 | D7: in Austria | E7: =C7*('CPI USA'!$E$12)*('CPI USA'!$B$80/'CPI USA'!$B$74) -> 16.853692
A8: 400 | B8: 0.1 | C8: 12.609138 | D8: in Austria | E8: =C8*('CPI USA'!$E$12)*('CPI USA'!$B$80/'CPI USA'!$B$74) -> 17.717984
A9: 400 | B9: 0.12 | C9: 13.121705 | D9: in Austria | E9: =C9*('CPI USA'!$E$12)*('CPI USA'!$B$80/'CPI USA'!$B$74) -> 18.438227
A10: 400 | B10: 0.14 | C10: 13.531758 | D10: in Austria | E10: =C10*('CPI USA'!$E$12)*('CPI USA'!$B$80/'CPI USA'!$B$74) -> 19.014422
A11: 400 | B11: 0.16 | C11: 13.736785 | D11: in Austria | E11: =C11*('CPI USA'!$E$12)*('CPI USA'!$B$80/'CPI USA'!$B$74) -> 19.302519
A12: 400 | B12: 0.18 | C12: 13.941812 | D12: in Austria | E12: =C12*('CPI USA'!$E$12)*('CPI USA'!$B$80/'CPI USA'!$B$74) -> 19.590616
A13: 400 | B13: 0.02 | C13: 6.1507992 | D13: in Austria | E13: =C13*('CPI USA'!$E$12)*('CPI USA'!$B$80/'CPI USA'!$B$74) -> 8.6429189
A14: 400 | B14: 0.04 | C14: 8.5086056 | D14: in Austria | E14: =C14*('CPI USA'!$E$12)*('CPI USA'!$B$80/'CPI USA'!$B$74) -> 11.956038
... A115: 400 | B115: 0.08 | C115: 14.864431 | D115: In Europe | E115: =C115*('CPI USA'!$E$12)*('CPI USA'!$B$80/'CPI USA'!$B$74) -> 20.887054

Sheet Agg Costs
A1: Aggregated Costs
A2: ID | B2: Year | C2: CCY | D2: Penetration level | E2: 2015 £/MWh | F2: 2017 €/MWh | G2: Region | H2: Notes | K2: Costs in 2023 USD
A3: 403/455 | B3: 2015 | C3: GBP | D3: 0.364 | E3: 6.4 | F3: 8.9942435 | G3: UK | H3: Offshore wind, CCC 2015 | K3: =F3*('CPI USA'!$E$12)*('CPI USA'!$B$80/'CPI USA'!$B$74) -> 12.638442
A4: 403/455 | B4: 2015 | C4: GBP | D4: 0.363 | E4: 13.6 | F4: 19.112767 | G4: UK | H4: Offshore wind, CCC 2015 | K4: =F4*('CPI USA'!$E$12)*('CPI USA'!$B$80/'CPI USA'!$B$74) -> 26.856688
A5: 403/455 | B5: 2015 | C5: GBP | D5: 0.361 | E5: 23 | F5: 32.323062 | G5: UK | H5: Offshore wind, CCC 2015 | K5: =F5*('CPI USA'!$E$12)*('CPI USA'!$B$80/'CPI USA'!$B$74) -> 45.419399
A6: 403/455 | B6: 2015 | C6: GBP | D6: 0.47 | E6: 36.9 | F6: 51.857435 | G6: UK | H6: Offshore wind, CCC 2015 | K6: =F6*('CPI USA'!$E$12)*('CPI USA'!$B$80/'CPI USA'!$B$74) -> 72.868515
A7: 403/455 | B7: 2015 | C7: GBP | D7: 0.48 | E7: 35.4 | F7: 49.749409 | G7: UK | H7: Offshore wind, CCC 2015 | K7: =F7*('CPI USA'!$E$12)*('CPI USA'!$B$80/'CPI USA'!$B$74) -> 69.90638
A8: 403/455 | B8: 2015 | C8: GBP | D8: 0.512 | E8: 13.9 | F8: 19.534373 | G8: UK | H8: Offshore wind, CCC 2015 | K8: =F8*('CPI USA'!$E$12)*('CPI USA'!$B$80/'CPI USA'!$B$74) -> 27.449115
A9: 403/455 | B9: 2015 | C9: GBP | D9: 0.518 | E9: 12.8 | F9: 17.988487 | G9: UK | H9: Offshore wind, CCC 2015 | K9: =F9*('CPI USA'!$E$12)*('CPI USA'!$B$80/'CPI USA'!$B$74) -> 25.276883
A10: 403/455 | B10: 2015 | C10: GBP | D10: 0.513 | E10: 7.1 | F10: 9.9779888 | G10: UK | H10: Offshore wind, CCC 2015 | K10: =F10*('CPI USA'!$E$12)*('CPI USA'!$B$80/'CPI USA'!$B$74) -> 14.020771
A11: 403/455 | B11: 2015 | C11: GBP | D11: 0.519 | E11: 8.2 | F11: 11.523874 | G11: UK | H11: Offshore wind, CCC 2015 | K11: =F11*('CPI USA'!$E$12)*('CPI USA'!$B$80/'CPI USA'!$B$74) -> 16.193003
A12: 456 | B12: 2015 | C12: GBP | D12: 0.266 | E12: 10.6 | F12: 14.896716 | G12: UK | H12: Offshore wind, No progress | K12: =F12*('CPI USA'!$E$12)*('CPI USA'!$B$80/'CPI USA'!$B$74) -> 20.932419
A13: 456 | B13: 2015 | C13: GBP | D13: 0.37 | E13: 31.8 | F13: 44.690147 | G13: UK | H13: Offshore wind, No progress | K13: =F13*('CPI USA'!$E$12)*('CPI USA'!$B$80/'CPI USA'!$B$74) -> 62.797257
A14: 456 | B14: 2015 | C14: GBP | D14: 0.504 | E14: 48.4 | F14: 68.018966 | G14: UK | H14: Offshore wind, No progress | K14: =F14*('CPI USA'!$E$12)*('CPI USA'!$B$80/'CPI USA'!$B$74) -> 95.578214
A15: 456 | B15: 2015 | C15: GBP | D15: 0.266 | E15: 10.2 | F15: 14.334576 | G15: UK | H15: Offshore wind, Moderate progress | K15: =F15*('CPI USA'!$E$12)*('CPI USA'!$B$80/'CPI USA'!$B$74) -> 20.142516
A16: 456 | B16: 2015 | C16: GBP | D16: 0.37 | E16: 11 | F16: 15.458856 | G16: UK | H16: Offshore wind, Moderate progress | K16: =F16*('CPI USA'!$E$12)*('CPI USA'!$B$80/'CPI USA'!$B$74) -> 21.722321
A17: 456 | B17: 2015 | C17: GBP | D17: 0.47 | E17: 11.2 | F17: 15.739926 | G17: UK | H17: Offshore wind, Moderate progress | K17: =F17*('CPI USA'!$E$12)*('CPI USA'!$B$80/'CPI USA'!$B$74) -> 22.117273
A18: 456 | B18: 2015 | C18: GBP | D18: 0.265 | E18: 6.6 | F18: 9.2753136 | G18: UK | H18: Offshore wind, Fast progress | K18: =F18*('CPI USA'!$E$12)*('CPI USA'!$B$80/'CPI USA'!$B$74) -> 13.033393
A19: 456 | B19: 2015 | C19: GBP | D19: 0.279 | E19: 7.4 | F19: 10.399594 | G19: UK | H19: Offshore wind, Fast progress | K19: =F19*('CPI USA'!$E$12)*('CPI USA'!$B$80/'CPI USA'!$B$74) -> 14.613198
A20: 456 | B20: 2015 | C20: GBP | D20: 0.355 | E20: 7.7 | F20: 10.821199 | G20: UK | H20: Offshore wind, Fast progress | K20: =F20*('CPI USA'!$E$12)*('CPI USA'!$B$80/'CPI USA'!$B$74) -> 15.205625
A21: 456 | B21: 2015 | C21: GBP | D21: 0.37 | E21: 7.6 | F21: 10.680664 | G21: UK | H21: Offshore wind, Fast progress | K21: =F21*('CPI USA'!$E$12)*('CPI USA'!$B$80/'CPI USA'!$B$74) -> 15.008149
A22: 456 | B22: 2015 | C22: GBP | D22: 0.415 | E22: 6.5 | F22: 9.1347785 | G22: UK | H22: Offshore wind, Fast progress | K22: =F22*('CPI USA'!$E$12)*('CPI USA'!$B$80/'CPI USA'!$B$74) -> 12.835917
A23: 456 | B23: 2015 | C23: GBP | D23: 0.46 | E23: 7.7 | F23: 10.821199 | G23: UK | H23: Offshore wind, Fast progress | K23: =F23*('CPI USA'!$E$12)*('CPI USA'!$B$80/'CPI USA'!$B$74) -> 15.205625
... A35: 456 | B35: 2015 | C35: GBP | D35: 0.589 | E35: 7.4 | F35: 10.399594 | G35: UK | H35: Offshore wind, Maximum progress | K35: =F35*('CPI USA'!$E$12)*('CPI USA'!$B$80/'CPI USA'!$B$74) -> 14.613198
A36: 403/455 | B36: 2015 | C36: GBP | D36: 0.362 | E36: 23 | F36: 32.323062 | G36: UK | H36: Onshore wind, CCC 2015 | K36: =F36*('CPI USA'!$E$12)*('CPI USA'!$B$80/'CPI USA'!$B$74) -> 45.419399
A37: 403/455 | B37: 2015 | C37: GBP | D37: 0.364 | E37: 13.5 | F37: 18.972232 | G37: UK | H37: Onshore wind, CCC 2015 | K37: =F37*('CPI USA'!$E$12)*('CPI USA'!$B$80/'CPI USA'!$B$74) -> 26.659213
A38: 403/455 | B38: 2015 | C38: GBP | D38: 0.364 | E38: 6.3 | F38: 8.8537084 | G38: UK | H38: Onshore wind, CCC 2015 | K38: =F38*('CPI USA'!$E$12)*('CPI USA'!$B$80/'CPI USA'!$B$74) -> 12.440966
A39: 403/455 | B39: 2015 | C39: GBP | D39: 0.471 | E39: 36.8 | F39: 51.7169 | G39: UK | H39: Onshore wind, CCC 2015 | K39: =F39*('CPI USA'!$E$12)*('CPI USA'!$B$80/'CPI USA'!$B$74) -> 72.671039
A40: 403/455 | B40: 2015 | C40: GBP | D40: 0.48 | E40: 35.4 | F40: 49.749409 | G40: UK | H40: Onshore wind, CCC 2015 | K40: =F40*('CPI USA'!$E$12)*('CPI USA'!$B$80/'CPI USA'!$B$74) -> 69.90638
A41: 403/455 | B41: 2015 | C41: GBP | D41: 0.513 | E41: 13.8 | F41: 19.393837 | G41: UK | H41: Onshore wind, CCC 2015 | K41: =F41*('CPI USA'!$E$12)*('CPI USA'!$B$80/'CPI USA'!$B$74) -> 27.25164
